<mujoco model="phybot_mini_mark2">
  <compiler angle="radian" meshdir="assets" autolimits="true"/>
  <option timestep="0.002" iterations='50' solver='PGS' gravity='0 0 -9.81'>
  </option>
  <size njmax="500" nconmax="100" />
  <default>
    <geom  condim='4' solref='0.001 2' friction='1.0 0.5 0.5'/>
    <equality solref='0.001 2'/>
  </default>
  <visual>
      <quality shadowsize='4096'/>
      <map force="0.1" zfar="30" znear='0.05'/>
      <rgba haze="0.15 0.25 0.35 1"/>
      <global offwidth="2560" offheight="1440" elevation="-20" azimuth="120"/>
  </visual>
  <default>
    <default class="phybot_mini_mark2">
      <joint damping="1" armature="0.1"/>
      <default class="visual">
        <geom type="mesh" contype="0" conaffinity="0" group="2" />
      </default>
      <default class="collision">
        <geom group="3" mass="0" density="0" friction="1.0 0.5 0.5" />
        <default class="foot_capsule">
          <geom type="capsule" size="0.01"/>
        </default>
      </default>
    </default>
  </default>

  <asset>
      <texture type="skybox" builtin="gradient" rgb1=".3 .5 .7" rgb2="0 0 0" width="32" height="512"/>
      <texture name="body" type="cube" builtin="flat" mark="cross" width="128" height="128" rgb1="0.8 0.6 0.4" rgb2="0.8 0.6 0.4" markrgb="1 1 1" random="0.01"/>
      <material name="body" texture="body" texuniform="true" rgba="0.8 0.6 .4 1"/>
      <texture name="grid" type="2d" builtin="checker" width="512" height="512" rgb1=".1 .2 .3" rgb2=".2 .3 .4"/>
      <material name="grid" texture="grid" texrepeat="1 1" texuniform="true" reflectance="0.02"/>
  </asset>
  <asset>
    <mesh name="base_link" file="base_link.STL"/>
    <mesh name="left_hip_pitch" file="left_hip_pitch.STL"/>
    <mesh name="left_hip_roll" file="left_hip_roll.STL"/>
    <mesh name="left_hip_yaw" file="left_hip_yaw.STL"/>
    <mesh name="left_knee" file="left_knee.STL"/>
    <mesh name="right_ankle_pitch" file="right_ankle_pitch.STL"/>
    <mesh name="left_ankle_roll" file="left_ankle_roll.STL"/>
    <mesh name="right_hip_pitch" file="right_hip_pitch.STL"/>
    <mesh name="right_hip_roll" file="right_hip_roll.STL"/>
    <mesh name="right_hip_yaw" file="right_hip_yaw.STL"/>
    <mesh name="right_knee" file="right_knee.STL"/>
    <mesh name="right_ankle_roll" file="right_ankle_roll.STL"/>
    <mesh name="torso" file="torso.STL"/>
    <mesh name="left_shoulder_pitch" file="left_shoulder_pitch.STL"/>
    <mesh name="left_shoulder_roll" file="left_shoulder_roll.STL"/>
    <mesh name="left_shoulder_yaw" file="left_shoulder_yaw.STL"/>
    <mesh name="left_elbow_pitch" file="left_elbow_pitch.STL"/>
    <mesh name="left_elbow_yaw" file="left_elbow_yaw.STL"/>
    <mesh name="right_shoulder_pitch" file="right_shoulder_pitch.STL"/>
    <mesh name="right_shoulder_roll" file="right_shoulder_roll.STL"/>
    <mesh name="right_shoulder_yaw" file="right_shoulder_yaw.STL"/>
    <mesh name="right_elbow_pitch" file="right_elbow_pitch.STL"/>
    <mesh name="right_elbow_yaw" file="right_elbow_yaw.STL"/>
    <mesh name="neck_yaw" file="neck_yaw.STL"/>
    <mesh name="neck_pitch" file="neck_pitch.STL"/>
    <texture builtin="gradient" height="100" rgb1=".4 .5 .6" rgb2="0 0 0" type="skybox" width="100"/>
    <texture name="texplane" type="2d" builtin="checker" rgb1=".2 .3 .4" rgb2=".1 0.15 0.2" width="100" height="100"/>
    <material name="MatPlane" reflectance="0.5" texture="texplane" texrepeat="1 1" texuniform="true"/>
  </asset>

  <worldbody>
  <geom name="floor" friction="1 .5 .5" pos="0 0 0.0" size="50 50 0.125" type="plane" material="MatPlane" condim="3" conaffinity="1" contype="1" group="2" rgba="0.8 0.9 0.8 1"/>
  <light cutoff="100" diffuse="1 1 1" dir="-0 0 -1.3" directional="true" exponent="1" pos="0 0 1.3" specular=".1 .1 .1" castshadow="false"/>
  <body name="base_link" pos="0 0.0 1.1" euler="0 0 1.5708" childclass="phybot_mini_mark2">
    <inertial pos="0.00029935 -1.8119e-07 0.023406" quat="0.999999 0.000213974 0.00165245 0.00039263" mass="3.5" diaginertia="0.01330575 0.01205119 0.00625631"/>
    <joint name="floating_base_joint" type="free" limited="false" actuatorfrclimited="false"/>
    <geom type="mesh" contype="0" conaffinity="0" group="1" density="0" rgba="0.86667 0.86667 0.8902 1" mesh="base_link"/>
    <geom name="base_link_collision" type="sphere" size="0.07" pos="0.00259459 0 0.00656728" rgba="0.86667 0.86667 0.8902 1"/>
    <body name="left_hip_pitch" pos="0 0.0578 -0.00010315">
      <inertial pos="-0.010451 0.062682 8.8167e-05" quat="0.083119 0.701134 -0.0837025 0.703204" mass="0.91049" diaginertia="0.000839681 0.000776212 0.000684886"/>
      <joint name="left_hip_pitch_joint" pos="0 0 0" axis="0 1 0" range="-2.62 2.62" actuatorfrcrange="-200 200"/>
      <geom pos="0 0 0" type="mesh" contype="0" conaffinity="0" group="1" density="0" rgba="0.86667 0.86667 0.8902 1" mesh="left_hip_pitch"/>
      <geom name="left_hip_pitch_collision" size="0.046" pos="-0.00436918 0.0615005 -0.00236015" rgba="0.86667 0.86667 0.8902 1"/>
      <body name="left_hip_roll" pos="0 0.0645 0.00010315">
        <inertial pos="0.017315 7.7056e-06 -0.027368" quat="0.938777 0.00153671 0.344522 0.000938653" mass="0.25544" diaginertia="0.000407279 0.00034617 0.000257411"/>
        <joint name="left_hip_roll_joint" pos="0 0 0" axis="1 0 0" range="-0.1 2.79" actuatorfrcrange="-80 80"/>
        <geom type="mesh" contype="0" conaffinity="0" group="1" density="0" rgba="0.86667 0.86667 0.8902 1" mesh="left_hip_roll"/>
        <body name="left_hip_yaw" pos="5.177e-05 0 -0.0555">
          <inertial pos="-0.000660698 -0.000269523 -0.0709022" quat="0.99961 -0.00783722 0.0251877 -0.00915786" mass="1.18423" diaginertia="0.00392986 0.00371214 0.0011681"/>
          <joint name="left_hip_yaw_joint" pos="0 0 0" axis="0 0 1" range="-2.09 2.09" actuatorfrcrange="-58 58"/>
          <geom type="mesh" contype="0" conaffinity="0" group="1" density="0" rgba="0.86667 0.86667 0.8902 1" mesh="left_hip_yaw"/>
          <geom name="left_hip_yaw_collision" size="0.044 0.06" pos="0 0 -0.1" type="capsule" rgba="0.86667 0.86667 0.8902 1"/>
          <body name="left_knee" pos="-0.015 0 -0.178">
            <inertial pos="0.00788863 8.73965e-05 -0.0948138" quat="0.661405 -0.0155255 -0.0140926 0.749736" mass="1.93631" diaginertia="0.0251976 0.0251419 0.00203863"/>
            <joint name="left_knee_joint" pos="0 0 0" axis="0.0011316 0.999999 0" range="0 2.44" actuatorfrcrange="-80 80"/>
            <geom type="mesh" contype="0" conaffinity="0" group="1" density="0" rgba="0.86667 0.86667 0.8902 1" mesh="left_knee"/>
            <geom name="left_knee_collision" size="0.042 0.075" pos="0 0 -0.16" type="capsule" rgba="0.86667 0.86667 0.8902 1"/>
            <body name="left_ankle_pitch" pos="0.015 0 -0.324">
              <inertial pos="-0.000464283 -0.000367434 -0.0356355" quat="0.997287 0.00504669 0.0068855 -0.0731111" mass="1.5" diaginertia="0.00275313 0.00275183 0.000964559"/>
              <joint name="left_ankle_pitch_joint" pos="0 0 0" axis="0.0011316 0.999999 0" range="-1.4 1.4" actuatorfrcrange="-58 58"/>
              <geom type="mesh" contype="0" conaffinity="0" group="1" density="0" rgba="0.86667 0.86667 0.8902 1" mesh="right_ankle_pitch"/>
              <geom name="left_ankle_pitch_collision" size="0.048" pos="0 0 -0.0209636" rgba="0.86667 0.86667 0.8902 1"/>
              <body name="left_ankle_roll" pos="0.038948 4.7715e-05 -0.069">
                <site name="left_foot" rgba="1 0 0 1" pos="0.04 0 -0.037"/>
                <inertial pos="-0.00706776 4.03562e-05 -0.0350697" quat="0.00111808 0.725531 0.0017096 0.688187" mass="1.36346" diaginertia="0.0069294 0.00649197 0.00171846"/>
                <joint name="left_ankle_roll_joint" pos="0 0 0" axis="1 0 0" range="-0.61 0.61" actuatorfrcrange="-58 58"/>
                <geom pos="0 0 0" type="mesh" contype="0" conaffinity="0" group="1" density="0" rgba="0.86667 0.86667 0.8902 1" mesh="left_ankle_roll"/>
<!--                <geom name="left_foot1_collision" size="0.012 0.1" pos="0.008 -0.024 -0.052" quat="0.000563312 0.707388 0.000562864 -0.706825" type="capsule" rgba="0.86667 0.86667 0.8902 1"/>-->
                <geom name="left_foot1_collision" class="foot_capsule" fromto="0.106 -0.026 -0.052 -0.099 -0.027 -0.052"/>
                <geom name="left_foot2_collision" class="foot_capsule" fromto="-0.102 -0.018 -0.052 0.112 -0.018 -0.052"/>
                <geom name="left_foot3_collision" class="foot_capsule" fromto="-0.106 -0.01 -0.052 0.118 -0.01 -0.052"/>
                <geom name="left_foot4_collision" class="foot_capsule" fromto="-0.11 0 -0.052 0.12 0 -0.052"/>
                <geom name="left_foot5_collision" class="foot_capsule" fromto="-0.106 0.01 -0.052 0.118 0.01 -0.052"/>
                <geom name="left_foot6_collision" class="foot_capsule" fromto="-0.102 0.018 -0.052 0.112 0.018 -0.052"/>
                <geom name="left_foot7_collision" class="foot_capsule" fromto="0.106 0.026 -0.052 -0.099 0.026 -0.052"/>
<!--                <geom name="left_foot7_collision" size="0.012 0.1" pos="0.008 0.024 -0.052" quat="0.000563312 0.707388 0.000562864 -0.706825" type="capsule" rgba="0.86667 0.86667 0.8902 1"/>-->
              </body>
            </body>
          </body>
        </body>
      </body>
    </body>
    <body name="right_hip_pitch" pos="0 -0.0598 0">
      <inertial pos="-0.0104986 -0.0606821 1.49808e-05" quat="-0.0841103 0.703157 0.0835219 0.701085" mass="0.910488" diaginertia="0.000839521 0.000776107 0.000684841"/>
      <joint name="right_hip_pitch_joint" pos="0 0 0" axis="0 1 0" range="-2.62 2.62" actuatorfrcrange="-200 200"/>
      <geom pos="0 0 0" type="mesh" contype="0" conaffinity="0" group="1" density="0" rgba="0.86667 0.86667 0.8902 1" mesh="right_hip_pitch"/>
      <geom name="right_hip_pitch_collision" size="0.046" pos="-0.00436918 -0.0615005 -0.00236015" rgba="0.86667 0.86667 0.8902 1"/>
      <body name="right_hip_roll" pos="0 -0.0625 0">
        <inertial pos="0.0172664 8.09741e-06 -0.0273683" quat="0.938745 0.0015365 0.344609 0.000938282" mass="0.255436" diaginertia="0.00040732 0.00034621 0.00025742"/>
        <joint name="right_hip_roll_joint" pos="0 0 0" axis="1 0 0" range="-2.79 0.1" actuatorfrcrange="-80 80"/>
        <geom type="mesh" contype="0" conaffinity="0" group="1" density="0" rgba="0.86667 0.86667 0.8902 1" mesh="right_hip_roll"/>
        <body name="right_hip_yaw" pos="0 0 -0.0555">
          <inertial pos="-0.00162439 0.000656584 -0.113596" quat="0.998814 0.0138718 0.0459246 0.00834949" mass="0.434265" diaginertia="0.00195143 0.00173094 0.000762913"/>
          <joint name="right_hip_yaw_joint" pos="0 0 0" axis="0 0 1" range="-2.09 2.9" actuatorfrcrange="-58 58"/>
          <geom type="mesh" contype="0" conaffinity="0" group="1" density="0" rgba="0.86667 0.86667 0.8902 1" mesh="right_hip_yaw"/>
          <geom name="right_hip_yaw_collision" size="0.044 0.06" pos="0 0 -0.1" type="capsule" rgba="0.86667 0.86667 0.8902 1"/>
          <body name="right_knee" pos="-0.015 0 -0.178">
            <inertial pos="0.00748147 0.000468573 -0.0967989" quat="0.723297 -0.0149086 -0.0167715 0.690173" mass="1.87028" diaginertia="0.0249554 0.0249148 0.00200181"/>
            <joint name="right_knee_joint" pos="0 0 0" axis="-0.0011316 0.999999 0" range="0 2.44" actuatorfrcrange="-80 80"/>
            <geom type="mesh" contype="0" conaffinity="0" group="1" density="0" rgba="0.86667 0.86667 0.8902 1" mesh="right_knee"/>
            <geom name="right_knee_collision" size="0.042 0.075" pos="0 0 -0.16" type="capsule" rgba="0.86667 0.86667 0.8902 1"/>
            <body name="right_ankle_pitch" pos="0.015 0 -0.324">
              <inertial pos="-0.00043695 0.000369141 -0.0400577" quat="0.999953 -0.00483678 0.00579502 0.0060279" mass="1.5" diaginertia="0.00323949 0.00323821 0.000964532"/>
              <joint name="right_ankle_pitch_joint" pos="0 0 0" axis="-0.0011316 0.999999 0" range="-1.4 1.4" actuatorfrcrange="-58 58"/>
              <geom type="mesh" contype="0" conaffinity="0" group="1" density="0" rgba="0.86667 0.86667 0.8902 1" mesh="right_ankle_pitch"/>
              <geom name="right_ankle_pitch_collision" size="0.048" pos="0 0 -0.0209636" rgba="0.86667 0.86667 0.8902 1"/>
              <body name="right_ankle_roll" pos="0.039 -4.436e-05 -0.08">
                <site name="right_foot" rgba="1 0 0 1" pos="0.04 0 -0.037"/>
                <inertial pos="-0.00935957 6.26081e-05 -0.025329" quat="0.00182563 0.727657 0.000844849 0.685938" mass="1.2444" diaginertia="0.00675175 0.00631519 0.00159091"/>
                <joint name="right_ankle_roll_joint" pos="0 0 0" axis="1 0 0" range="-0.61 0.61" actuatorfrcrange="-58 58"/>
                <geom type="mesh" contype="0" conaffinity="0" group="1" density="0" rgba="0.86667 0.86667 0.8902 1" mesh="right_ankle_roll"/>
<!--                <geom name="right_foot1_collision" size="0.012 0.1" pos="0.008 0.024 -0.042" quat="0.000563312 0.707388 0.000562864 -0.706825" type="capsule" rgba="0.86667 0.86667 0.8902 1"/>-->
<!--                <geom name="right_foot2_collision" size="0.012 0.1" pos="0.008 -0.024 -0.042" quat="0.000563312 0.707388 0.000562864 -0.706825" type="capsule" rgba="0.86667 0.86667 0.8902 1"/>-->
                <geom name="right_foot1_collision" class="foot_capsule" fromto="0.106 -0.026 -0.042 -0.099 -0.026 -0.042"/>
                <geom name="right_foot2_collision" class="foot_capsule" fromto="-0.102 -0.018 -0.042 0.112 -0.018 -0.042"/>
                <geom name="right_foot3_collision" class="foot_capsule" fromto="-0.106 -0.01 -0.042 0.118 -0.01 -0.042"/>
                <geom name="right_foot4_collision" class="foot_capsule" fromto="-0.11 0 -0.042 0.12 0 -0.042"/>
                <geom name="right_foot5_collision" class="foot_capsule" fromto="-0.106 0.01 -0.042 0.118 0.01 -0.042"/>
                <geom name="right_foot6_collision" class="foot_capsule" fromto="-0.102 0.018 -0.042 0.112 0.018 -0.042"/>
                <geom name="right_foot7_collision" class="foot_capsule" fromto="0.106 0.026 -0.042 -0.099 0.026 -0.042"/>
              </body>
            </body>
          </body>
        </body>
      </body>
    </body>
    <body name="waist_yaw" pos="0 0 0.255">
      <inertial pos="-0.000621633 -0.00060824 0.0627254" quat="0.999923 -0.000821252 -0.0121552 -0.00232251" mass="8.843" diaginertia="0.120218 0.108604 0.0328178"/>
      <joint name="waist_yaw_joint" pos="0 0 0" axis="0 0 1" range="-2.62 2.62" actuatorfrcrange="-58 58"/>
      <geom type="mesh" contype="0" conaffinity="0" group="1" density="0" rgba="0.86667 0.86667 0.8902 1" mesh="torso"/>
      <geom name="waist_yaw_collision" size="0.063 0.09 0.125" pos="0.00027658 0.0003768 0" type="box" rgba="0.86667 0.86667 0.8902 1"/>
      <geom pos="0 0 0.148" type="mesh" contype="0" conaffinity="0" group="1" density="0" rgba="0.86667 0.86667 0.8902 1" mesh="neck_yaw"/>
      <geom pos="0 0 0.2075" type="mesh" contype="0" conaffinity="0" group="1" density="0" rgba="0.86667 0.86667 0.8902 1" mesh="neck_pitch"/>
      <geom name="head_collision" size="0.07" pos="0 0 0.263466" rgba="0.86667 0.86667 0.8902 1"/>
      <body name="left_shoulder_pitch" pos="0 0.1065 0.099">
        <inertial pos="0.00071542 0.053508 -3.9443e-09" quat="0.5078 0.492077 -0.5078 0.492077" mass="0.783062" diaginertia="0.00061796 0.000532075 0.000496755"/>
        <joint name="left_shoulder_pitch_joint" pos="0 0 0" axis="0 1 0" range="-2.62 2.62" actuatorfrcrange="-58 58"/>
        <geom pos="0 0 0" type="mesh" contype="0" conaffinity="0" group="1" density="0" rgba="0.86667 0.86667 0.8902 1" mesh="left_shoulder_pitch"/>
        <geom name="left_shoulder_pitch_collision" size="0.042" pos="0 0.059495 0" rgba="0.86667 0.86667 0.8902 1"/>
        <body name="left_shoulder_roll" pos="0 0.0575 0">
          <inertial pos="0.022804 0.0039333 -0.017788" quat="0.940833 0.102634 0.321036 0.0351355" mass="0.17719" diaginertia="0.000256392 0.000194645 0.000139602"/>
          <joint name="left_shoulder_roll_joint" pos="0 0 0" axis="1 0 0" range="-0.26 2.62" actuatorfrcrange="-58 58"/>
          <geom type="mesh" contype="0" conaffinity="0" group="1" density="0" rgba="0.86667 0.86667 0.8902 1" mesh="left_shoulder_roll"/>
          <body name="left_shoulder_yaw" pos="0.00125 0.0097398 -0.043933" quat="0.994056 0.108869 0 0">
            <inertial pos="-0.00020494 -0.0060826 -0.12095" quat="0.997368 0.0724149 -0.00112664 0.00331653" mass="1.24393" diaginertia="0.00517735 0.00508953 0.000754096"/>
            <joint name="left_shoulder_yaw_joint" pos="0 0 0" axis="0 0 1" range="-1.75 1.75" actuatorfrcrange="-9 9"/>
            <geom type="mesh" contype="0" conaffinity="0" group="1" density="0" rgba="0.86667 0.86667 0.8902 1" mesh="left_shoulder_yaw"/>
            <geom name="left_shoulder_yaw_collision" size="0.034 0.05" pos="0 0 -0.0868437" type="capsule" rgba="0.86667 0.86667 0.8902 1"/>
            <body name="left_elbow_pitch" pos="0 0 -0.163">
              <inertial pos="-0.00164426 -0.00265918 -0.140605" quat="0.974282 0.00758825 -0.012909 -0.224834" mass="1.06257" diaginertia="0.0069157 0.00687241 0.000534144"/>
              <joint name="left_elbow_pitch_joint" pos="0 0 0" axis="0 1 0" range="-2.27 0.05" actuatorfrcrange="-58 58"/>
              <geom pos="0 0 0" type="mesh" contype="0" conaffinity="0" group="1" density="0" rgba="0.86667 0.86667 0.8902 1" mesh="left_elbow_pitch"/>
              <geom name="left_elbow_pitch_collision" size="0.032 0.036" pos="0 -0.00576669 -0.072571" type="capsule" rgba="0.86667 0.86667 0.8902 1"/>
              <geom pos="0.0001107 -0.00525 -0.147" type="mesh" contype="0" conaffinity="0" group="1" density="0" rgba="0.86667 0.86667 0.8902 1" mesh="left_elbow_yaw"/>
              <geom name="left_waist_collision" size="0.028 0.04034" pos="0.000163931 -0.00524999 -0.227688" quat="1 3.143e-08 -0.00037652 8.3475e-05" type="capsule" rgba="0.86667 0.86667 0.8902 1"/>
            </body>
          </body>
        </body>
      </body>
      <body name="right_shoulder_pitch" pos="0 -0.1065 0.099">
        <inertial pos="0.000715418 -0.0535077 3.94432e-09" quat="0.492077 0.5078 -0.492077 0.5078" mass="0.783062" diaginertia="0.00061796 0.000532075 0.000496755"/>
        <joint name="right_shoulder_pitch_joint" pos="0 0 0" axis="0 1 0" range="-2.62 2.62" actuatorfrcrange="-58 58"/>
        <geom pos="0 0 0" type="mesh" contype="0" conaffinity="0" group="1" density="0" rgba="0.86667 0.86667 0.8902 1" mesh="right_shoulder_pitch"/>
        <geom name="right_shoulder_pitch_collision" size="0.042" pos="0 -0.059495 0" rgba="0.86667 0.86667 0.8902 1"/>
        <body name="right_shoulder_roll" pos="0 -0.0575 0">
          <inertial pos="0.0228047 -0.00395395 -0.0177819" quat="0.940632 -0.103353 0.321391 -0.0351805" mass="0.177189" diaginertia="0.000256475 0.000194466 0.00013972"/>
          <joint name="right_shoulder_roll_joint" pos="0 0 0" axis="1 0 0" range="-2.62 0.26" actuatorfrcrange="-58 58"/>
          <geom type="mesh" contype="0" conaffinity="0" group="1" density="0" rgba="0.86667 0.86667 0.8902 1" mesh="right_shoulder_roll"/>
          <body name="right_shoulder_yaw" pos="0.00125 -0.0097398 -0.043933" quat="0.994056 -0.108869 0 0">
            <inertial pos="-0.000488895 0.00349494 -0.0642143" quat="0.582591 -0.0233421 0.0367723 0.811598" mass="0.51393" diaginertia="0.00151826 0.00151437 0.000271098"/>
            <joint name="right_shoulder_yaw_joint" pos="0 0 0" axis="0 0 1" range="-1.75 1.75" actuatorfrcrange="-9 9"/>
            <geom type="mesh" contype="0" conaffinity="0" group="1" density="0" rgba="0.86667 0.86667 0.8902 1" mesh="right_shoulder_yaw"/>
            <geom name="right_shoulder_yaw_collision" size="0.034 0.05" pos="0 0 -0.0868437" type="capsule" rgba="0.86667 0.86667 0.8902 1"/>
            <body name="right_elbow_pitch" pos="0 0 -0.163">
              <inertial pos="-0.00163129 -0.0037679 -0.140601" quat="0.974683 -0.00789963 -0.0126972 0.223092" mass="1.06261" diaginertia="0.00691615 0.00687272 0.000534756"/>
              <joint name="right_elbow_pitch_joint" pos="0 0 0" axis="0 1 0" range="-2.27 0.05" actuatorfrcrange="-58 58"/>
              <geom type="mesh" contype="0" conaffinity="0" group="1" density="0" rgba="0.86667 0.86667 0.8902 1" mesh="right_elbow_pitch"/>
              <geom name="right_elbow_pitch_collision" size="0.032 0.036" pos="0 0.00576669 -0.072571" type="capsule" rgba="0.86667 0.86667 0.8902 1"/>
              <geom pos="0.0001107 -0.00125 -0.147" type="mesh" contype="0" conaffinity="0" group="1" density="0" rgba="0.86667 0.86667 0.8902 1" mesh="right_elbow_yaw"/>
              <geom name="right_waist_collision" size="0.028 0.04034" pos="0.000163931 -0.00125001 -0.227688" quat="1 -3.143e-08 -0.00037652 -8.3475e-05" type="capsule" rgba="0.86667 0.86667 0.8902 1"/>
            </body>
          </body>
        </body>
      </body>
    </body>
    <body name="imu_link" pos="-0.0 0 0.0">
      <inertial pos="0 0 0" mass="0" diaginertia="0 0 0" />
      <geom class="visual" type="sphere" rgba="0.792157 0.819608 0.933333 1" size="0.02" />
      <site name="site_imu" pos="0.01 0 0" size='0.01 0.01 0.01' group="4"/>
    </body>
  </body>
  </worldbody>
<!--  <actuator>-->
<!--      <motor name="left_hip_pitch" joint="left_hip_pitch_joint" gear="1" ctrllimited="true" ctrlrange="-500 500" />-->
<!--      <motor name="left_hip_roll" joint="left_hip_roll_joint" gear="1" ctrllimited="true" ctrlrange="-200 200" />-->
<!--      <motor name="left_hip_yaw" joint="left_hip_yaw_joint" gear="1" ctrllimited="true" ctrlrange="-200 200" />-->
<!--      <motor name="left_knee" joint="left_knee_joint" gear="1" ctrllimited="true" ctrlrange="-500 500" />-->
<!--      <motor name="left_ankle_pitch" joint="left_ankle_pitch_joint" gear="1" ctrllimited="true" ctrlrange="-200.0 200.0" />-->
<!--      <motor name="left_ankle_roll" joint="left_ankle_roll_joint" gear="1" ctrllimited="true" ctrlrange="-30 30" />-->
<!--      <motor name="right_hip_pitch" joint="right_hip_pitch_joint" gear="1" ctrllimited="true" ctrlrange="-500 500" />-->
<!--      <motor name="right_hip_roll" joint="right_hip_roll_joint" gear="1" ctrllimited="true" ctrlrange="-200 200" />-->
<!--      <motor name="right_hip_yaw" joint="right_hip_yaw_joint" gear="1" ctrllimited="true" ctrlrange="-200 200" />-->
<!--      <motor name="right_knee" joint="right_knee_joint" gear="1" ctrllimited="true" ctrlrange="-500 500" />-->
<!--      <motor name="right_ankle_pitch" joint="right_ankle_pitch_joint" gear="1" ctrllimited="true" ctrlrange="-200.0 200.0" />-->
<!--      <motor name="right_ankle_roll" joint="right_ankle_roll_joint" gear="1" ctrllimited="true" ctrlrange="-30 30" />-->
<!--      <motor name="waist_yaw" joint="waist_yaw_joint" gear="1" ctrllimited="true" ctrlrange="-230 230" />-->
<!--      <motor name="left_shoulder_pitch" joint="left_shoulder_pitch_joint" gear="1" ctrllimited="true" ctrlrange="-200 200" />-->
<!--      <motor name="left_shoulder_roll" joint="left_shoulder_roll_joint" gear="1" ctrllimited="true" ctrlrange="-200 200" />-->
<!--      <motor name="left_shoulder_yaw" joint="left_shoulder_yaw_joint" gear="1" ctrllimited="true" ctrlrange="-58 58" />-->
<!--      <motor name="left_elbow_pitch" joint="left_elbow_pitch_joint" gear="1" ctrllimited="true" ctrlrange="-58 58" />-->
<!--      <motor name="right_shoulder_pitch" joint="right_shoulder_pitch_joint" gear="1" ctrllimited="true" ctrlrange="-200 200" />-->
<!--      <motor name="right_shoulder_roll" joint="right_shoulder_roll_joint" gear="1" ctrllimited="true" ctrlrange="-200 200" />-->
<!--      <motor name="right_shoulder_yaw" joint="right_shoulder_yaw_joint" gear="1" ctrllimited="true" ctrlrange="-58 58" />-->
<!--      <motor name="right_elbow_pitch" joint="right_elbow_pitch_joint" gear="1" ctrllimited="true" ctrlrange="-58 58" />-->
<!--  </actuator>-->
  <sensor>
    <accelerometer name="imu_acc" site="site_imu" noise="0.005" cutoff="157"/>
    <framequat name="orientation" objtype="site" noise="0.001" objname="site_imu"/>
    <framepos name="position" objtype="site" noise="0.001" objname="site_imu"/>
    <gyro name="imu_ang_vel" site="site_imu" noise="0.005" cutoff="34.9"/>
    <velocimeter name="imu_lin_vel" site="site_imu" noise="0.001" cutoff="30"/>
    <magnetometer name="magnetometer" site="site_imu"/>
    <subtreeangmom name="root_angmom" body="base_link"/>
  </sensor>

<!--  <keyframe>-->
<!--    <key name="home"-->
<!--      qpos="0 0 0.70 1 0 0 0 -->
<!--      -0.15 0 0 0.3 -0.15 0 -0.15 0 0 0.3 -0.15 0-->
<!--       0 0 0 0 0 0 0 0 0" />-->
<!--  </keyframe>-->

</mujoco>
